Workbook

Sheet Summary
B2: Client Name - HOOPP (Healthcare of Ontario Pension Plan) | F2: Services Entitlements
B3: General Details | C3: Live Since | F3: Services | G3: Entitled | H3: Comments
C4: Client Time Zone | D4: EST | F4: Application Monitoring(AM) - PROD | G4: Yes
C5: Business Hrs. | D5: 8:00am to 5:00pm | F5: Business Assistance(BA) | G5: No
B6: Client Contact Details | C6: Mailing Group | D6: goldensourceoperations@hoopp.com | F6: Custom Configuration Management(CM) | G6: Yes
B8: Implementation Details | C8: Application Version | D8: 8.9.0
C9: Modules | D9: Security Master
D10: Price Master | F10: Workload Details IST
F11: Shift | G11: Timing | H11: Workload
C12: GoldenCopy | D12: Yes | F12: Night | G12: 12:00am to 04:00am | H12: High
C13: VDDB | D13: Yes | F13: Night-Morning | G13: 04:00am to 08:00am | H13: High
C14: DWH | D14: No | F14: Morning | G14: 08:00am to 12:00pm | H14: Low
C15: Insight | D15: Yes | F15: Morning-Afternoon | G15: 12:00pm to 04:00pm | H15: Low
C16: Talend | D16: No | F16: Afternoon | G16: 04:00pm to 08:00pm | H16: Low
C17: Scheduler | D17: Job Scheduler | F17: Afternoon-Night | G17: 08:00pm to 12:00am | H17: High
C18: Clustered | D18: No
C19: App. Server | D19: Jboss
C20: Queue Config | D20: No
B21: Vendor Details | C21: Bloomberg | D21: http://service.bloomberg.com Urgent issues: 1-212-617-4390 Global Technical Support: 1-212-318-2000
C22: Markit | D22: support@markit.com red@ihsmarkit.com CALL THIS NUMBER - GOES TO ALL INDIA SUPPORT STAFF: +91 120 611 8051 MK-ValHOOPP@ihsmarkit.com Kamal.Sehgal@ihsmarkit.com Vrinda.Pal@ihsmarkit.com Managers: Sachin.Singhal@ihsmarkit.com Rajesh.Kumar2@ihsmarkit.com Toronto Staff: spencer.wiseman@ihsmarkit.com Abhinit.Kumar@ihsmarkit.com
C23: S&P | D23: Product.Notification <Product.Notification@spglobal.com>
C24: FTSE | D24: PC-Bond Index Team <pcbond@FTSERussell.com> Always CC: Info@ftserussell.com Front Desk: Phone: 1-866-551-0617
C25: S&P Index | D25: Index_services@spdji.com index_services@spglobal.com Phone: 1-212-438-2046
C26: SVC | D26: dco@ssnc.com SVC-ClientSupport@sscinc.com Portch, Glenn <gportch@sscinc.com> Garito, Nick <ngarito@sscinc.com> Martinis, Peter pmartinis@sscinc.com call 905 629-8000 and choose prompt #1, then prompt #7 for SVC
C27: ICE | D27: icelinksupport@theice.com icelinkhelp@theice.com
C28: Simcorp | D28: goldensourceoperations@hoopp.com for now HOOPP To CHECK INTERNALLY
C29: Moody's | D29: goldensourceoperations@hoopp.com for now HOOPP To CHECK INTERNALLY
B30: EST to IST | C30: 9.5

Sheet ADayInLife(ADITLO)
A1: ic | B1: Depends Job # | C1: Job Category | D1: Parent Workflow | E1: Job Chain Name | F1: Sub-Application | G1: Task Name in Job Scheduler | H1: Schema | I1: Node | J1: Task Type | K1: Input or Output File Names | L1: FileName | M1: Time Trigerred (CST/CDT) | N1: Time Trigerred (EST/EDT) | O1: Time Trigerred Until (EST) | P1: Time Trigerred (IST) | Q1: Timeline(EST) | R1: File polling interval | S1: Alerts for Fileload | T1: Frequency | U1: Holiday Calendar Followed | V1: Event/ Script Used | W1: Properties files | X1: Part of Regression Testing | Y1: File Path on the AS or JNM FTP | Z1: Summary of the Job | AA1: UC4 workflow | AB1: Critical Job? | AC1: Avg. Time to Finish | AD1: Business SLO (EST) | AE1: OMNI SLO (EST) | AF1: Max Alert Threshold (mins) | AG1: Configured Alerts | AH1: Alert Send To | AI1: Vendor Details | AJ1: Instructions/Actions | AK1: Escalation Path | AL1: OMNI Readiness Check File Name | AM1: OMNI PIpeline Name to Check | AN1: OMNI Readiness Check File Name Date (considering Effective Date = T) | AO1: Job Chain Run Date (considering Effective Date = T) E.g. T+1 means Monday's data will be loaded on Tuesday | AV1: UC4 SLO (EST)
AO2: Mon | AP2: Tue | AQ2: Wed | AR2: Thu | AS2: Fri | AT2: Sat | AU2: Sun
A3: =MAX(A$1:A1)+1 -> 1 | B3: 31 | C3: Standalone | D3: EQUITY | E3: Standalone | F3: Price Master | G3: HOOPP_BB_Generic_Schedule/HOOPP_BB_GENERIC_Req_FileLoad | H3: GC | J3: BB Request | K3: BB Generic Req | L3: GS.BB.GENERIC.out.20240828 | N3: 0.97916667 | O3: =N3 + TIME(2, 0, 0) -> 1.0625 | P3: =N3+Summary!$C$30/24 -> 1.375 | Q3: T+1 | T3: Daily(Mon-Fri) | AB3: Y | AD3: 0.020833333 | AE3: 0.052083333 | AH3: File Load Alert - GS MS Only (GS to chase Vendor directly) SLO Alert - GS MS, HOOPP | AI3: http://service.bloomberg.com Urgent issues: 1-212-617-4390 Global Technical Support: 1-212-318-2000; DXC Contact: DXC Overnight Tier 1 <dxcovernighttier1@hoopp.com> | AJ3: PLEASE SPECIFY WHAT IS IN THIS FILE SMF OR PRICE FILES?
A4: 2 | B4: 1 | C4: Standalone | D4: EQUITY | E4: Standalone | F4: Price Master | G4: HOOPP_BB_Generic_Resp_Schedule/HOOPP_BB_Trig_GENERIC_FileLoad | H4: GC | J4: FileLoad | K4: BB Generic Response | L4: GS.BB.GENERIC.out.20240828 | N4: 0.98958333 | O4: =N4 + TIME(2, 0, 0) -> 1.0729167 | P4: =N4+Summary!$C$30/24 -> 1.3854167 | Q4: T+1 | R4: Every 1 min | S4: 15 mins | T4: Daily(Mon-Fri) | AB4: Y | AD4: 0.041666667 | AE4: 0.052083333 | AG4: HOOPP_BB_Trig_GENERIC_FileLoad | AH4: File Load Alert - GS MS Only (GS to chase Vendor directly) SLO Alert - GS MS, HOOPP | AI4: http://service.bloomberg.com Urgent issues: 1-212-617-4390 Global Technical Support: 1-212-318-2000; DXC Contact: DXC Overnight Tier 1 <dxcovernighttier1@hoopp.com> | AJ4: PLEASE SPECIFY WHAT IS IN THIS FILE SMF OR PRICE FILES?
A5: 4 | D5: EQUITY | G5: HOOPP_BB_CAX_Req_FileLoad | H5: GC | J5: BB Request | K5: BB Corporate Action Request | L5: GS.BB.CAX.out.20240828 | N5: 0.00069444444 | P5: =N5+(Summary!$C$30)/24 -> 0.39652778 | Q5: T+1 | T5: Daily(Mon-Sun) | AB5: Y | AD5: 0.0625 | AE5: 0.072916667 | AH5: File Load Alert - GS MS Only (GS to chase Vendor directly) SLO Alert - GS MS, HOOPP | AI5: http://service.bloomberg.com Urgent issues: 1-212-617-4390 Global Technical Support: 1-212-318-2000; DXC Contact: DXC Overnight Tier 1 <dxcovernighttier1@hoopp.com> | AJ5: PLEASE SPECIFY WHAT IS IN THIS FILE SMF OR PRICE FILES? | AL5: GS.BB.CAX.out.YYYYMMDD | AM5: GoldenSource Security Reference Pipeline | AN5: T+1 | AO5: T+1 | AP5: T+1 | AQ5: T+1 | AR5: T+1 | AS5: T+1 | AT5: T+1 | AU5: T+1 | AV5: 0.079861111
A6: 3 | B6: 31,2 | C6: Standalone | D6: EQUITY | E6: Standalone | F6: Price Master | G6: HOOPP_BB_ALL_Req_FileLoad | H6: GC | J6: BB Request | K6: BB All Asset Class Request except FX(Currency) | L6: GS.BB.EQFND.out.20240828 GS.BB.CURNCY.out.20240828 GS.BB.NONEQOPT.out.20240828 GS.BB.EQTY.out.20240828 GS.BB.MUNI.out.20240828 GS.BB.EQWRNT.out.20240828 GS.BB.GENTICKERS.out.20240828 GS.BB.EQOPTINDX.out.20240828 GS.BB.CP.out.20240828 GS.BB.PFD.out.20240828 GS.BB.CORPGOV.out.20240828 GS.BB.MTGE.out.20240828 GS.BB.MMKT.out.20240828 | N6: 0.00069444444 | O6: =N6 + TIME(2, 0, 0) -> 0.084027778 | P6: =N6+Summary!$C$30/24 -> 0.39652778 | Q6: T+1 | T6: Daily(Tue-Sat) | AB6: Y | AD6: 0.0625 | AE6: 0.072916667 | AH6: File Load Alert - GS MS Only (GS to chase Vendor directly) SLO Alert - GS MS, HOOPP | AI6: http://service.bloomberg.com Urgent issues: 1-212-617-4390 Global Technical Support: 1-212-318-2000; DXC Contact: DXC Overnight Tier 1 <dxcovernighttier1@hoopp.com> | AJ6: PLEASE SPECIFY WHAT IS IN THIS FILE SMF OR PRICE FILES?
A7: 35.1 | C7: Standalone | D7: MARKIT | E7: Standalone | G7: HOOPP_MOTC_DAILY_SG_FileLoad / HOOPP_MOTC_DAILY_SG_FileLoad_Monday | J7: Fileload | K7: Markit OTC Fileload | L7: HOOPP_SG_DAILY.01Nov24.csv | N7: 0.041666667 | O7: 0.16666667 | Q7: T+1 | R7: Every 10 min | T7: Daily(Mon-Fri) | U7: MARKIT_HOLIDAYPLUS1 | AD7: 0.16666667 | AE7: 0.1875 | AG7: HOOPP_MOTC_DAILY_SG_FileLoad | AI7: Vendor Technical Contact: General support@spglobal.com index_services@spglobal.com Michael.Stone@ihsmarkit.com For any escalation or urgent request: referencedataclientservice@spglobal.com SFTP issues: data.delivery@ihsmarkit.com CALL THIS NUMBER - GOES TO ALL INDIA SUPPORT STAFF: +91 120 611 8051 MK-ValHOOPP@ihsmarkit.com Kamal.Sehgal@ihsmarkit.com Vrinda.Pal@ihsmarkit.com Managers: Sachin.Singhal@ihsmarkit.com Rajesh.Kumar2@ihsmarkit.com Toronto Staff: spencer.wiseman@ihsmarkit.com Abhinit.Kumar@ihsmarkit.com Red red@spglobal.com support@spglobal.com Markit Vol OTCDD@spglobal.com After Hours support: +1 877 762 7548 Corporate Action markitcorporateactions@ihsmarkit.com managedcorporateactions@ihsmarkit.com support@markit.com PE Vals (related to CIFC) MK-PEHOOPP@ihsmarkit.com DL-PE-PEValsSupport@ihsmarkit.com Ashwani.Rai@ihsmarkit.com Vendor Business Contact: Lucas Pettella's Team - 1st point of contact Portfolio Valuation: MK-ValHOOPP@ihsmarkit.com (sydney.workman@spglobal.com, nikita.zinchenko@spglobal.com) CDS Pricing Data: cdssupport@ihsmarkit.com EBS (Formerly known as DeltaOne): DeltaOneSupport@ihsmarkit.com OTC Derivatives Data: OTCDD@spglobal.com CDS Reference Data: red@spglobal.com Iboxx Indices: indices@ihsmarkit.com Cameron Lounsbery (Director - Account Management) Email: Cameron.Lounsbery@spglobal.com Phone: (416)304-6587
A8: 35.2 | C8: Standalone | D8: MARKIT | E8: Standalone | G8: HOOPP_MOTC_DAILY_SG_2_FileLoad / HOOPP_MOTC_DAILY_SG_2_FileLoad_Monday | J8: Fileload | K8: Markit OTC Fileload | L8: HOOPP_SG_DAILY_2.01Nov24.csv | N8: 0.041666667 | O8: 0.16666667 | Q8: T+1 | R8: Every 10 min | T8: Daily(Mon-Fri) | U8: MARKIT_HOLIDAYPLUS1 | AD8: 0.16666667 | AE8: 0.1875 | AG8: HOOPP_MOTC_DAILY_SG_2_FileLoad | AI8: Vendor Technical Contact: General support@spglobal.com index_services@spglobal.com Michael.Stone@ihsmarkit.com For any escalation or urgent request: referencedataclientservice@spglobal.com SFTP issues: data.delivery@ihsmarkit.com CALL THIS NUMBER - GOES TO ALL INDIA SUPPORT STAFF: +91 120 611 8051 MK-ValHOOPP@ihsmarkit.com Kamal.Sehgal@ihsmarkit.com Vrinda.Pal@ihsmarkit.com Managers: Sachin.Singhal@ihsmarkit.com Rajesh.Kumar2@ihsmarkit.com Toronto Staff: spencer.wiseman@ihsmarkit.com Abhinit.Kumar@ihsmarkit.com Red red@spglobal.com support@spglobal.com Markit Vol OTCDD@spglobal.com After Hours support: +1 877 762 7548 Corporate Action markitcorporateactions@ihsmarkit.com managedcorporateactions@ihsmarkit.com support@markit.com PE Vals (related to CIFC) MK-PEHOOPP@ihsmarkit.com DL-PE-PEValsSupport@ihsmarkit.com Ashwani.Rai@ihsmarkit.com Vendor Business Contact: Lucas Pettella's Team - 1st point of contact Portfolio Valuation: MK-ValHOOPP@ihsmarkit.com (sydney.workman@spglobal.com, nikita.zinchenko@spglobal.com) CDS Pricing Data: cdssupport@ihsmarkit.com EBS (Formerly known as DeltaOne): DeltaOneSupport@ihsmarkit.com OTC Derivatives Data: OTCDD@spglobal.com CDS Reference Data: red@spglobal.com Iboxx Indices: indices@ihsmarkit.com Cameron Lounsbery (Director - Account Management) Email: Cameron.Lounsbery@spglobal.com Phone: (416)304-6587
A9: 35.3 | B9: 35.1 | D9: MARKIT | F9: Price Master | G9: HOOPP_PricePublishing_OTC HOOPP_PricePublishing_OTC_DAILY | J9: Markit OTC Price Publishing (Silver+Gold) - Price Derivation - Price Valication - Price Denorm - Price Publishing | K9: Price Publishing | L9: Gold-copy for: MarkitSOI_CDX_TRANCHE MarkitSOI_BESPOKE | N9: 0.041666667 | O9: 0.125 | Q9: T+1 | T9: Daily(Tue-Sat) Daily(Mon-Fri) | U9: MARKIT_HOLIDAYPLUS1 | AD9: 0.16666667 | AE9: 0.1875 | AG9: HOOPP_PricePublishing_OTC_DAILY | AL9: HOOPP_SG_DAILY.DDMonYY.csv | AM9: GoldenSource Market Data Solution Hub Pipeline | AN9: T (on Mo this is Friday) | AO9: T+1 | AP9: T+1 | AQ9: T+1 | AR9: T+1 | AS9: T+3 | AV9: 0.19444444
A10: 35.4 | B10: 35.2 | D10: MARKIT | F10: Price Master | G10: HOOPP_PricePublishing_OTC HOOPP_PricePublishing_OTC_DAILY_2 | J10: Markit OTC Price Publishing (Silver+Gold) - Price Derivation - Price Valication - Price Denorm - Price Publishing | K10: Price Publishing | L10: Gold-copy for: MarkitSOI_ABX MarkitSOI_CDX_OPT | N10: 0.041666667 | O10: 0.125 | Q10: T+1 | T10: Daily(Tue-Sat) Daily(Mon-Fri) | U10: MARKIT_HOLIDAYPLUS1 | AD10: 0.16666667 | AE10: 0.1875 | AG10: HOOPP_PricePublishing_OTC_DAILY_2 | AL10: HOOPP_SG_DAILY_2.DDMonYY.csv | AM10: GoldenSource Market Data Solution Hub Pipeline | AN10: T | AO10: T+1 | AP10: T+1 | AQ10: T+1 | AR10: T+1 | AS10: T+3 | AV10: 0.19444444
A11: 5 | B11: 3 | C11: Standalone | D11: EQUITY | E11: Standalone | F11: Price Master | G11: HOOPP_BB_ALL_Resp_FileLoad | H11: GC | J11: FileLoad | K11: BB All Asset Response | L11: GS.BB.EQFND.out.20240828 GS.BB.CURNCY.out.20240828 GS.BB.NONEQOPT.out.20240828 GS.BB.EQTY.out.20240828 GS.BB.MUNI.out.20240828 GS.BB.EQWRNT.out.20240828 GS.BB.GENTICKERS.out.20240828 GS.BB.EQOPTINDX.out.20240828 GS.BB.CP.out.20240828 GS.BB.PFD.out.20240828 GS.BB.CORPGOV.out.20240828 GS.BB.MTGE.out.20240828 GS.BB.MMKT.out.20240828 | N11: 0.017361111 | O11: =N11 + TIME(2, 0, 0) -> 0.10069444 | P11: =N11+(Summary!$C$30)/24 -> 0.41319444 | Q11: T+1 | R11: Every 1 min | S11: 15 mins | T11: Daily(Tue-Sat) | AB11: Y | AD11: 0.0625 | AE11: 0.072916667 | AG11: HOOPP_BB_ALL_Resp_FileLoad | AH11: File Load Alert - GS MS Only (GS to chase Vendor directly) SLO Alert - GS MS, HOOPP | AI11: http://service.bloomberg.com Urgent issues: 1-212-617-4390 Global Technical Support: 1-212-318-2000; DXC Contact: DXC Overnight Tier 1 <dxcovernighttier1@hoopp.com> | AJ11: PLEASE SPECIFY WHAT IS IN THIS FILE SMF OR PRICE FILES? | AL11: GS.BB.EQTY.out.YYYYMMDD | AM11: GoldenSource Security Reference Pipeline | AN11: T+1 | AO11: T+1 | AP11: T+1 | AQ11: T+1 | AR11: T+1 | AS11: T+1 | AV11: 0.079861111
A12: 6 | B12: 4 | C12: Standalone | D12: EQUITY | E12: Standalone | G12: HOOPP_BB_Trig_CAX_FileLoad | H12: GC | J12: FileLoad | K12: BB Corporate Action Response | L12: GS.BB.CAX.out.20240828 | N12: 0.027777778 | O12: =N12 + TIME(2, 0, 0) -> 0.11111111 | P12: =N12+(Summary!$C$30)/24 -> 0.42361111 | Q12: T+1 | R12: Every 1 min | S12: 15 mins | T12: Daily(Mon-Sun) | AD12: 0.125 | AE12: 0.072916667 | AG12: HOOPP_BB_Trig_CAX_FileLoad | AH12: File Load Alert - GS MS Only (GS to chase Vendor directly) SLO Alert - GS MS, HOOPP | AI12: http://service.bloomberg.com Urgent issues: 1-212-617-4390 Global Technical Support: 1-212-318-2000; DXC Contact: DXC Overnight Tier 1 <dxcovernighttier1@hoopp.com> | AL12: GS.BB.CAX.out.YYYYMMDD | AM12: GoldenSource Security Reference Pipeline | AN12: T+1 | AO12: T+1 | AP12: T+1 | AQ12: T+1 | AR12: T+1 | AS12: T+1 | AT12: T+1 | AU12: T+1 | AV12: 0.079861111
A13: 8 | C13: Standalone | E13: Standalone | G13: HOOPP_Markit_REDEntity_FileLoad | H13: GC | J13: FileLoad | K13: Markit RED Obligation | L13: V10%20Red%20Obligation1724826602201.xml V11%20Red%20Obligation1724826602201.xml | N13: 0.10416667 | O13: =N13 + TIME(2, 0, 0) -> 0.1875 | P13: =N13+(Summary!$C$30)/24 -> 0.5 | Q13: T+1 | R13: Every 5 mins | S13: 16 mins | T13: Daily(Mon-Fri) Daily(Tue-Sat) | AD13: 0.14583333 | AE13: 0.15625 | AG13: HOOPP_Markit_REDEntity_FileLoad | AH13: File Load Alert - GS MS Only (GS to chase Vendor directly) SLO Alert - GS MS, HOOPP | AI13: Vendor Technical Contact: General support@spglobal.com index_services@spglobal.com Michael.Stone@ihsmarkit.com For any escalation or urgent request: referencedataclientservice@spglobal.com SFTP issues: data.delivery@ihsmarkit.com CALL THIS NUMBER - GOES TO ALL INDIA SUPPORT STAFF: +91 120 611 8051 MK-ValHOOPP@ihsmarkit.com Kamal.Sehgal@ihsmarkit.com Vrinda.Pal@ihsmarkit.com Managers: Sachin.Singhal@ihsmarkit.com Rajesh.Kumar2@ihsmarkit.com Toronto Staff: spencer.wiseman@ihsmarkit.com Abhinit.Kumar@ihsmarkit.com Red red@spglobal.com support@spglobal.com Markit Vol OTCDD@spglobal.com After Hours support: +1 877 762 7548 Corporate Action markitcorporateactions@ihsmarkit.com managedcorporateactions@ihsmarkit.com support@markit.com PE Vals (related to CIFC) MK-PEHOOPP@ihsmarkit.com DL-PE-PEValsSupport@ihsmarkit.com Ashwani.Rai@ihsmarkit.com Vendor Business Contact: Lucas Pettella's Team - 1st point of contact Portfolio Valuation: MK-ValHOOPP@ihsmarkit.com (sydney.workman@spglobal.com, nikita.zinchenko@spglobal.com) CDS Pricing Data: cdssupport@ihsmarkit.com EBS (Formerly known as DeltaOne): DeltaOneSupport@ihsmarkit.com OTC Derivatives Data: OTCDD@spglobal.com CDS Reference Data: red@spglobal.com Iboxx Indices: indices@ihsmarkit.com Cameron Lounsbery (Director - Account Management) Email: Cameron.Lounsbery@spglobal.com Phone: (416)304-6587 | AL13: V11_Red_Obligation_YYYYMMDD.xml | AM13: GoldenSource Security Reference Pipeline | AN13: T+1 | AO13: T+1 | AP13: T+1 | AQ13: T+1 | AR13: T+1 | AS13: T+1 | AV13: 0.16319444
A14: 9 | C14: Standalone | E14: Standalone | G14: HOOPP_Markit_REDEntity_FileLoad | H14: GC | J14: FileLoad | K14: Markit RED Entity | L14: V11%20Red%20Entity1724826870563.xml V12_Red_Entity_20250219.xml | N14: 0.10416667 | O14: =N14 + TIME(2, 0, 0) -> 0.1875 | P14: =N14+(Summary!$C$30)/24 -> 0.5 | Q14: T+1 | R14: Every 5 mins | S14: 16 mins | T14: Daily(Mon-Fri) Daily(Tue-Sat) | AD14: 0.14583333 | AE14: 0.15625 | AG14: HOOPP_Markit_REDEntity_FileLoad | AH14: File Load Alert - GS MS Only (GS to chase Vendor directly) SLO Alert - GS MS, HOOPP | AI14: Vendor Technical Contact: General support@spglobal.com index_services@spglobal.com Michael.Stone@ihsmarkit.com For any escalation or urgent request: referencedataclientservice@spglobal.com SFTP issues: data.delivery@ihsmarkit.com CALL THIS NUMBER - GOES TO ALL INDIA SUPPORT STAFF: +91 120 611 8051 MK-ValHOOPP@ihsmarkit.com Kamal.Sehgal@ihsmarkit.com Vrinda.Pal@ihsmarkit.com Managers: Sachin.Singhal@ihsmarkit.com Rajesh.Kumar2@ihsmarkit.com Toronto Staff: spencer.wiseman@ihsmarkit.com Abhinit.Kumar@ihsmarkit.com Red red@spglobal.com support@spglobal.com Markit Vol OTCDD@spglobal.com After Hours support: +1 877 762 7548 Corporate Action markitcorporateactions@ihsmarkit.com managedcorporateactions@ihsmarkit.com support@markit.com PE Vals (related to CIFC) MK-PEHOOPP@ihsmarkit.com DL-PE-PEValsSupport@ihsmarkit.com Ashwani.Rai@ihsmarkit.com Vendor Business Contact: Lucas Pettella's Team - 1st point of contact Portfolio Valuation: MK-ValHOOPP@ihsmarkit.com (sydney.workman@spglobal.com, nikita.zinchenko@spglobal.com) CDS Pricing Data: cdssupport@ihsmarkit.com EBS (Formerly known as DeltaOne): DeltaOneSupport@ihsmarkit.com OTC Derivatives Data: OTCDD@spglobal.com CDS Reference Data: red@spglobal.com Iboxx Indices: indices@ihsmarkit.com Cameron Lounsbery (Director - Account Management) Email: Cameron.Lounsbery@spglobal.com Phone: (416)304-6587 | AL14: V12_Red_Entity_YYYYMMDD.xml | AM14: GoldenSource Security Reference Pipeline | AN14: T+1 | AO14: T+1 | AP14: T+1 | AQ14: T+1 | AR14: T+1 | AS14: T+1 | AV14: 0.16319444
A15: 10 | C15: Standalone | D15: MARKIT | E15: Standalone | F15: Price Master | G15: HOOPP_CreditIndexPricing_FileLoad | H15: GC | J15: FileLoad | K15: Markit Credit Index Price (T-1) | L15: New_Credit_Index_Pricing_20240827.zip New_Credit_Index_Pricing_20240827.zip New_Credit_Index_Pricing_20240827.zip | N15: 0.0625 | O15: =N15 + TIME(2, 0, 0) -> 0.14583333 | P15: =N15+(Summary!$C$30)/24 -> 0.45833333 | Q15: T+1 | R15: Every 5 mins | S15: 16 mins | T15: Daily(Tue-Sat) | AD15: 0.14583333 | AE15: 0.15625 | AG15: HOOPP_CreditIndexPricing_FileLoad | AH15: File Load Alert - GS MS Only (GS to chase Vendor directly) SLO Alert - GS MS, HOOPP | AI15: Vendor Technical Contact: General support@spglobal.com index_services@spglobal.com Michael.Stone@ihsmarkit.com For any escalation or urgent request: referencedataclientservice@spglobal.com SFTP issues: data.delivery@ihsmarkit.com CALL THIS NUMBER - GOES TO ALL INDIA SUPPORT STAFF: +91 120 611 8051 MK-ValHOOPP@ihsmarkit.com Kamal.Sehgal@ihsmarkit.com Vrinda.Pal@ihsmarkit.com Managers: Sachin.Singhal@ihsmarkit.com Rajesh.Kumar2@ihsmarkit.com Toronto Staff: spencer.wiseman@ihsmarkit.com Abhinit.Kumar@ihsmarkit.com Red red@spglobal.com support@spglobal.com Markit Vol OTCDD@spglobal.com After Hours support: +1 877 762 7548 Corporate Action markitcorporateactions@ihsmarkit.com managedcorporateactions@ihsmarkit.com support@markit.com PE Vals (related to CIFC) MK-PEHOOPP@ihsmarkit.com DL-PE-PEValsSupport@ihsmarkit.com Ashwani.Rai@ihsmarkit.com Vendor Business Contact: Lucas Pettella's Team - 1st point of contact Portfolio Valuation: MK-ValHOOPP@ihsmarkit.com (sydney.workman@spglobal.com, nikita.zinchenko@spglobal.com) CDS Pricing Data: cdssupport@ihsmarkit.com EBS (Formerly known as DeltaOne): DeltaOneSupport@ihsmarkit.com OTC Derivatives Data: OTCDD@spglobal.com CDS Reference Data: red@spglobal.com Iboxx Indices: indices@ihsmarkit.com Cameron Lounsbery (Director - Account Management) Email: Cameron.Lounsbery@spglobal.com Phone: (416)304-6587 | AJ15: Update to reflect 3 file loads | AV15: 0.15625
A16: 10.1 | B16: 10 | D16: MARKIT | F16: Price Master | G16: HOOPP_PricePublishing_MarkitSOI_CDX_CDS | J16: Markit OTC Price Publishing (Silver+Gold) - Price Derivation - Price Valication - Price Denorm - Price Publishing | K16: Price Publishing | L16: Silver & gold for MarkitSOI_CDX_CDS Silver prices & key figures for all Markit Credit Index securities | N16: 0.0625 | O16: 0.1875 | Q16: T+1 | T16: Daily(Tue-Sat) | AD16: 0.14583333 | AE16: 0.15625 | AG16: HOOPP_PricePublishing_MarkitSOI_CDX_CDS | AL16: New_Credit_Index_Pricing_YYYYMMDD.zip | AM16: GoldenSource Market Data Solution Hub Pipeline | AN16: T | AO16: T+1 | AP16: T+1 | AQ16: T+1 | AR16: T+1 | AS16: T+1 | AV16: 0.16319444
A17: 10.2 | B17: 36, 10 | D17: MARKIT | F17: Price Master | G17: HOOPP_PricePublishing_MarkitSOI_CDX_CDS | J17: Markit OTC Price Publishing (Silver+Gold) - Price Derivation - Price Valication - Price Denorm - Price Publishing | K17: Price Publishing | L17: Silver & gold for MarkitSOI_CC_CDX_CDS | N17: 0.0625 | O17: 0.1875 | Q17: T+1 | T17: Daily(Tue-Sat) | AD17: 0.14583333 | AE17: 0.15625 | AG17: HOOPP_PricePublishing_MarkitSOI_CDX_CDS | AL17: New_Credit_Index_Pricing_YYYYMMDD.zip | AM17: GoldenSource Market Data Solution Hub Pipeline | AN17: T | AO17: T+1 | AP17: T+1 | AQ17: T+1 | AR17: T+1 | AS17: T+1 | AV17: 0.16319444
A18: 11 | C18: Standalone | D18: MARKIT | E18: Standalone | F18: Price Master | G18: HOOPP_CreditIndexPricing_FileLoad HOOPP_CDSBasicPricing_FileLoad | H18: GC | J18: FileLoad | K18: Markit Composite CDS Basic Pricing(T-1) | L18: Composite_CDS_Basic_Pricing_20240827.zip | N18: 0.0625 | O18: =N18 + TIME(2, 0, 0) -> 0.14583333 | P18: =N18+(Summary!$C$30)/24 -> 0.45833333 | Q18: T+1 | R18: Every 5 mins | S18: 16 mins | T18: Daily(Tue-Sat) | AD18: 0.125 | AE18: 0.14583333 | AG18: HOOPP_CDSBasicPricing_FileLoad | AH18: File Load Alert - GS MS Only (GS to chase Vendor directly) SLO Alert - GS MS, HOOPP | AI18: Vendor Technical Contact: General support@spglobal.com index_services@spglobal.com Michael.Stone@ihsmarkit.com For any escalation or urgent request: referencedataclientservice@spglobal.com SFTP issues: data.delivery@ihsmarkit.com CALL THIS NUMBER - GOES TO ALL INDIA SUPPORT STAFF: +91 120 611 8051 MK-ValHOOPP@ihsmarkit.com Kamal.Sehgal@ihsmarkit.com Vrinda.Pal@ihsmarkit.com Managers: Sachin.Singhal@ihsmarkit.com Rajesh.Kumar2@ihsmarkit.com Toronto Staff: spencer.wiseman@ihsmarkit.com Abhinit.Kumar@ihsmarkit.com Red red@spglobal.com support@spglobal.com Markit Vol OTCDD@spglobal.com After Hours support: +1 877 762 7548 Corporate Action markitcorporateactions@ihsmarkit.com managedcorporateactions@ihsmarkit.com support@markit.com PE Vals (related to CIFC) MK-PEHOOPP@ihsmarkit.com DL-PE-PEValsSupport@ihsmarkit.com Ashwani.Rai@ihsmarkit.com Vendor Business Contact: Lucas Pettella's Team - 1st point of contact Portfolio Valuation: MK-ValHOOPP@ihsmarkit.com (sydney.workman@spglobal.com, nikita.zinchenko@spglobal.com) CDS Pricing Data: cdssupport@ihsmarkit.com EBS (Formerly known as DeltaOne): DeltaOneSupport@ihsmarkit.com OTC Derivatives Data: OTCDD@spglobal.com CDS Reference Data: red@spglobal.com Iboxx Indices: indices@ihsmarkit.com Cameron Lounsbery (Director - Account Management) Email: Cameron.Lounsbery@spglobal.com Phone: (416)304-6587 | AV18: 0.14583333
A19: 11.1 | B19: 11 | D19: MARKIT | F19: Price Master | J19: Markit Composite CDS Price Publishing (Silver) - Price Denorm - Price Publishing | K19: Price Publishing | L19: Silver prices & key figures for all Markit Spread securities | N19: 0.10416667 | O19: 0.1875 | Q19: T+1 | T19: Daily(Tue-Sat) | AD19: 0.125 | AE19: 0.14583333 | AG19: HOOPP_PricePublishing_Markit_Schedule | AV19: 0.14583333
A20: 12 | C20: Standalone | E20: Standalone | G20: HOOPP_BB_CreditRisk_FileLoad | H20: GC | J20: FileLoad | K20: BB Corporate Structure(T-1) | L20: creditRiskV3.dif.gz | N20: 0.78125 | O20: =N20 + TIME(2, 0, 0) -> 0.86458333 | P20: =N20+(Summary!$C$30)/24 -> 1.1770833 | Q20: T+1 | R20: Every 10 mins | S20: 21 mins | T20: Daily(Mon-Sun) | Z20: Issuer data, No SOI | AD20: 0.8125 | AE20: 0.82291667 | AG20: HOOPP_BB_CreditRisk_FileLoad | AH20: File Load Alert - GS MS Only (GS to chase Vendor directly) SLO Alert - GS MS, HOOPP | AI20: http://service.bloomberg.com Urgent issues: 1-212-617-4390 Global Technical Support: 1-212-318-2000 | AL20: creditRiskV3.dif.gz | AM20: GoldenSource Security Reference Pipeline | AN20: NA (Date not available in the filename) | AO20: T | AP20: T | AQ20: T | AR20: T | AS20: T | AT20: T | AU20: T | AV20: 0.82986111
A21: 13 | C21: Standalone | E21: Standalone | G21: HOOPP_Moodys_FileLoad | H21: GC | J21: FileLoad | K21: Moody's RDS Instrument Ratings(24Hour delta) | L21: cfg_inst_current_rating_00_Utf8_24Hour_Delta_000028_20240828_000000_part01_0110final.split cfg_inst_current_rating_00_Utf8_24Hour_Delta_000028_20240828_000000_part01_0111final.split cfg_inst_current_rating_00_Utf8_24Hour_Delta_000028_20240828_000000_part01_0115final.split cfg_inst_current_rating_00_Utf8_24Hour_Delta_000028_20240828_000000_part01_011final.split cfg_inst_current_rating_00_Utf8_24Hour_Delta_000028_20240828_000000_part01_012final.split cfg_inst_current_rating_00_Utf8_24Hour_Delta_000028_20240828_000000_part01_013final.split cfg_inst_current_rating_00_Utf8_24Hour_Delta_000028_20240828_000000_part01_014final.split cfg_inst_current_rating_00_Utf8_24Hour_Delta_000028_20240828_000000_part01_015final.split cfg_inst_current_rating_00_Utf8_24Hour_Delta_000028_20240828_000000_part01_016final.split cfg_inst_current_rating_00_Utf8_24Hour_Delta_000028_20240828_000000_part01_017final.split cfg_inst_current_rating_00_Utf8_24Hour_Delta_000028_20240828_000000_part01_018final.split | N21: 0.875 | O21: =N21 + TIME(2, 0, 0) -> 0.95833333 | P21: =N21+([1]Summary!$C$30)/24 -> 0.875 | Q21: T | R21: Every 10 mins | S21: 21 mins | T21: Daily(Mon-Sat) Daily(Sun-Fri) | AD21: 0.91666667 | AE21: 0.92708333 | AG21: HOOPP_Moodys_FileLoad | AH21: File Load Alert - GS MS Only (GS to chase Vendor directly) SLO Alert - GS MS, HOOPP | AI21: Maura Bermiss: Maura.Bermiss@moodys.com | AL21: cfg_inst_current_rating_00_Utf8_24Hour_Delta_0000DD_YYYYMMDD_000000_part01*.split | AM21: GoldenSource Security Reference Pipeline | AN21: T+1 | AO21: T | AP21: T | AQ21: T | AR21: T | AS21: T | AU21: T | AV21: 0.93402778
A22: 14 | C22: Standalone | E22: Standalone | G22: HOOPP_Moodys_FileLoad | H22: GC | J22: FileLoad | K22: Moody's RDS Organization Ratings (24Hour delta) | L22: cfg_organization_current_rating_00_Utf8_24Hour_Delta_000028_20240828_000000_part01_010.split cfg_organization_current_rating_00_Utf8_24Hour_Delta_000028_20240828_000000_part01_011.split cfg_organization_current_rating_00_Utf8_24Hour_Delta_000028_20240828_000000_part01_012.split cfg_organization_current_rating_00_Utf8_24Hour_Delta_000028_20240828_000000_part01_013.split cfg_organization_current_rating_00_Utf8_24Hour_Delta_000028_20240828_000000_part01_014.split cfg_organization_current_rating_00_Utf8_24Hour_Delta_000028_20240828_000000_part01_015.split cfg_organization_current_rating_00_Utf8_24Hour_Delta_000028_20240828_000000_part01_016.split | N22: 0.875 | O22: =N22 + TIME(2, 0, 0) -> 0.95833333 | P22: =N22+([1]Summary!$C$30)/24 -> 0.875 | Q22: T | R22: Every 10 mins | S22: 21 mins | T22: Daily(Mon-Sat) Daily(Sun-Fri) | AD22: 0.91666667 | AE22: 0.92708333 | AG22: HOOPP_Moodys_FileLoad | AH22: File Load Alert - GS MS Only (GS to chase Vendor directly) SLO Alert - GS MS, HOOPP | AI22: Maura Bermiss: Maura.Bermiss@moodys.com | AL22: cfg_organization_current_rating_00_Utf8_24Hour_Delta_0000DD_YYYYMMDD_000000_part01*.split | AM22: GoldenSource Security Reference Pipeline | AN22: T+1 | AO22: T | AP22: T | AQ22: T | AR22: T | AS22: T | AU22: T | AV22: 0.93402778
A23: 7 | B23: 5 | D23: EQUITY | F23: Price Master | H23: GC | J23: BB Silver + Equities Gold Prices - Price Derivation - Price Valication - Price Denorm - Price Publishing | K23: Price Publishing | N23: 0.052083333 | P23: =N23+(Summary!$C$30)/24 -> 0.44791667 | Q23: T+1 | T23: Daily(Tue-Sat) | AD23: 0.083333333 | AE23: 0.09375 | AG23: HOOPP_PricePublishing_Equity_Schedule | AL23: GS.BB.EQTY.out.YYYYMMDD | AM23: GoldenSource Market Data Solution Hub Pipeline | AN23: T+1 | AO23: T+1 | AP23: T+1 | AQ23: T+1 | AR23: T+1 | AS23: T+1 | AV23: 0.10069444
A24: 33 | C24: Standalone | E24: Standalone | G24: HOOPP_Moodys_FullFile_FileLoad | H24: GC | J24: FileLoad | K24: Moody's RDS Instrument Ratings(baseline) | L24: cfg_inst_current_rating_Utf8_Baseline_Daily_20241027_000000_part09_0995final.split cfg_inst_current_rating_Utf8_Baseline_Daily_20241027_000000_part09_0999final.split cfg_inst_current_rating_Utf8_Baseline_Daily_20241027_000000_part09_0998final.split cfg_inst_current_rating_Utf8_Baseline_Daily_20241027_000000_part09_0988final.split cfg_inst_current_rating_Utf8_Baseline_Daily_20241027_000000_part09_0992final.split | N24: 0.875 | O24: =N24 + TIME(2, 0, 0) -> 0.95833333 | P24: =N24+([1]Summary!$C$30)/24 -> 0.875 | Q24: T | R24: Every 10 mins | S24: 30 mins | T24: Sat | AD24: 0.91666667 | AE24: 0.92708333 | AH24: File Load Alert - GS MS Only (GS to chase Vendor directly) SLO Alert - GS MS, HOOPP | AI24: Maura Bermiss: Maura.Bermiss@moodys.com | AL24: cfg_inst_current_rating_Utf8_Baseline_Daily_YYYYMMDD_000000_part01*.split | AM24: GoldenSource Security Reference Pipeline | AN24: T+1 | AT24: T | AV24: 0.93402778
A25: 34 | C25: Standalone | E25: Standalone | G25: HOOPP_Moodys_FullFile_FileLoad | H25: GC | J25: FileLoad | K25: Moody's RDS Organization Ratings (baseline) | L25: cfg_organization_current_rating_Utf8_Baseline_Daily_20241027_000000_part03_0499.split cfg_organization_current_rating_Utf8_Baseline_Daily_20241027_000000_part03_0498.split cfg_organization_current_rating_Utf8_Baseline_Daily_20241027_000000_part03_0497.split cfg_organization_current_rating_Utf8_Baseline_Daily_20241027_000000_part03_0495.split | N25: 0.875 | O25: =N25 + TIME(2, 0, 0) -> 0.95833333 | P25: =N25+([1]Summary!$C$30)/24 -> 0.875 | Q25: T | R25: Every 10 mins | S25: 30 mins | T25: Sat | AD25: 0.91666667 | AE25: 0.92708333 | AH25: File Load Alert - GS MS Only (GS to chase Vendor directly) SLO Alert - GS MS, HOOPP | AI25: Maura Bermiss: Maura.Bermiss@moodys.com | AL25: cfg_organization_current_rating_Utf8_Baseline_Daily_YYYYMMDD_000000_part01*.split | AM25: GoldenSource Security Reference Pipeline | AN25: T+1 | AT25: T | AV25: 0.93402778
A26: 15 | C26: Standalone | E26: Standalone | G26: HOOPP_SCD_4AM_FileLoad | H26: GC | J26: FileLoad | K26: Simcorp | L26: SCD_SMF_280824040122.csv | N26: 0.16666667 | O26: =N26 + TIME(2, 0, 0) -> 0.25 | P26: =N26+(Summary!$C$30)/24 -> 0.5625 | Q26: T+1 | R26: Every 3 mins | S26: 10 mins | T26: Daily(Mon-Sat) | AB26: y | AD26: 0.1875 | AE26: 0.20833333 | AG26: HOOPP_SCD_4AM_FileLoad | AH26: File Load Alert - GS MS Only (GS to chase Vendor directly) SLO Alert - GS MS, HOOPP | AI26: DXC Overnight Tier 1 <dxcovernighttier1@hoopp.com>; Golden Source Operations <goldensourceoperations@hoopp.com>; ISG-DTS-Operations <isg-dts-operations@hoopp.com> | AV26: 0.20833333
A27: 16 | G27: HOOPP_Markit_REDINDICES_CDX_FileLoad | H27: GC | J27: FileLoad | K27: Markit RED Credit Indices CDX | L27: V10%20Red%20Indices1724832057006.xml V11_CDX_Red_Indices_20250129.xml V11_CDX_Red_Indices_20250129.xml.inxdup V11_CDX_Red_Indices_20250129.xml.dedup | N27: 0.16666667 | O27: =N27 + TIME(2, 0, 0) -> 0.25 | P27: =N27+(Summary!$C$30)/24 -> 0.5625 | Q27: T+1 | R27: Every 5 mins | S27: 16 mins | T27: Daily(Mon-Fri) Daily(Tue-Sat) | AD27: 0.1875 | AE27: 0.21875 | AG27: HOOPP_Markit_REDINDICES_CDX_FileLoad | AH27: File Load Alert - GS MS Only (GS to chase Vendor directly) SLO Alert - GS MS, HOOPP | AI27: Vendor Technical Contact: General support@spglobal.com index_services@spglobal.com Michael.Stone@ihsmarkit.com For any escalation or urgent request: referencedataclientservice@spglobal.com SFTP issues: data.delivery@ihsmarkit.com CALL THIS NUMBER - GOES TO ALL INDIA SUPPORT STAFF: +91 120 611 8051 MK-ValHOOPP@ihsmarkit.com Kamal.Sehgal@ihsmarkit.com Vrinda.Pal@ihsmarkit.com Managers: Sachin.Singhal@ihsmarkit.com Rajesh.Kumar2@ihsmarkit.com Toronto Staff: spencer.wiseman@ihsmarkit.com Abhinit.Kumar@ihsmarkit.com Red red@spglobal.com support@spglobal.com Markit Vol OTCDD@spglobal.com After Hours support: +1 877 762 7548 Corporate Action markitcorporateactions@ihsmarkit.com managedcorporateactions@ihsmarkit.com support@markit.com PE Vals (related to CIFC) MK-PEHOOPP@ihsmarkit.com DL-PE-PEValsSupport@ihsmarkit.com Ashwani.Rai@ihsmarkit.com Vendor Business Contact: Lucas Pettella's Team - 1st point of contact Portfolio Valuation: MK-ValHOOPP@ihsmarkit.com (sydney.workman@spglobal.com, nikita.zinchenko@spglobal.com) CDS Pricing Data: cdssupport@ihsmarkit.com EBS (Formerly known as DeltaOne): DeltaOneSupport@ihsmarkit.com OTC Derivatives Data: OTCDD@spglobal.com CDS Reference Data: red@spglobal.com Iboxx Indices: indices@ihsmarkit.com Cameron Lounsbery (Director - Account Management) Email: Cameron.Lounsbery@spglobal.com Phone: (416)304-6587 | AL27: V11_CDX_Red_Indices_YYYYMMDD.xml | AM27: GoldenSource Security Reference Pipeline | AN27: T+1 | AO27: T+1 | AP27: T+1 | AQ27: T+1 | AR27: T+1 | AS27: T+1 | AV27: 0.22569444
A28: 17 | G28: HOOPP_Markit_REDINDICES_CDX_FileLoad | H28: GC | J28: FileLoad | K28: Markit RED Credit Indices EURO | L28: V10%20Red%20Indices%20Dynamic1724832001075.xml V11_ITRAXX-EUROPE_Red_Indices_20250129.xml V11_ITRAXX-EUROPE_Red_Indices_20250129.xml.inxdup V11_ITRAXX-EUROPE_Red_Indices_20250129.xml.dedup | N28: 0.16666667 | O28: =N28 + TIME(2, 0, 0) -> 0.25 | P28: =N28+(Summary!$C$30)/24 -> 0.5625 | Q28: T+1 | R28: Every 5 mins | S28: 16 mins | T28: Daily(Mon-Fri) Daily(Tue-Sat) | AD28: 0.1875 | AE28: 0.21875 | AG28: HOOPP_Markit_REDINDICES_CDX_FileLoad | AH28: File Load Alert - GS MS Only (GS to chase Vendor directly) SLO Alert - GS MS, HOOPP | AI28: Vendor Technical Contact: General support@spglobal.com index_services@spglobal.com Michael.Stone@ihsmarkit.com For any escalation or urgent request: referencedataclientservice@spglobal.com SFTP issues: data.delivery@ihsmarkit.com CALL THIS NUMBER - GOES TO ALL INDIA SUPPORT STAFF: +91 120 611 8051 MK-ValHOOPP@ihsmarkit.com Kamal.Sehgal@ihsmarkit.com Vrinda.Pal@ihsmarkit.com Managers: Sachin.Singhal@ihsmarkit.com Rajesh.Kumar2@ihsmarkit.com Toronto Staff: spencer.wiseman@ihsmarkit.com Abhinit.Kumar@ihsmarkit.com Red red@spglobal.com support@spglobal.com Markit Vol OTCDD@spglobal.com After Hours support: +1 877 762 7548 Corporate Action markitcorporateactions@ihsmarkit.com managedcorporateactions@ihsmarkit.com support@markit.com PE Vals (related to CIFC) MK-PEHOOPP@ihsmarkit.com DL-PE-PEValsSupport@ihsmarkit.com Ashwani.Rai@ihsmarkit.com Vendor Business Contact: Lucas Pettella's Team - 1st point of contact Portfolio Valuation: MK-ValHOOPP@ihsmarkit.com (sydney.workman@spglobal.com, nikita.zinchenko@spglobal.com) CDS Pricing Data: cdssupport@ihsmarkit.com EBS (Formerly known as DeltaOne): DeltaOneSupport@ihsmarkit.com OTC Derivatives Data: OTCDD@spglobal.com CDS Reference Data: red@spglobal.com Iboxx Indices: indices@ihsmarkit.com Cameron Lounsbery (Director - Account Management) Email: Cameron.Lounsbery@spglobal.com Phone: (416)304-6587 | AL28: V11_ITRAXX-EUROPE_Red_Indices_YYYYMMDD.xml | AM28: GoldenSource Security Reference Pipeline | AN28: T+1 | AO28: T+1 | AP28: T+1 | AQ28: T+1 | AR28: T+1 | AS28: T+1 | AV28: 0.22569444
A29: 18 | G29: HOOPP_Markit_REDINDICES_CDX_FileLoad | H29: GC | J29: FileLoad | K29: Markit RED Credit Indices ASIA | L29: V10%20Red%20Indices%20Dynamic1724832091625.xml V11_ITRAXX-ASIA_Red_Indices_20250129.xml V11_ITRAXX-ASIA_Red_Indices_20250129.xml.inxdup V11_ITRAXX-ASIA_Red_Indices_20250129.xml.dedup | N29: 0.16666667 | O29: =N29 + TIME(2, 0, 0) -> 0.25 | P29: =N29+(Summary!$C$30)/24 -> 0.5625 | Q29: T+1 | R29: Every 5 mins | S29: 16 mins | T29: Daily(Mon-Fri) Daily(Tue-Sat) | AD29: 0.1875 | AE29: 0.21875 | AG29: HOOPP_Markit_REDINDICES_CDX_FileLoad | AH29: File Load Alert - GS MS Only (GS to chase Vendor directly) SLO Alert - GS MS, HOOPP | AI29: Vendor Technical Contact: General support@spglobal.com index_services@spglobal.com Michael.Stone@ihsmarkit.com For any escalation or urgent request: referencedataclientservice@spglobal.com SFTP issues: data.delivery@ihsmarkit.com CALL THIS NUMBER - GOES TO ALL INDIA SUPPORT STAFF: +91 120 611 8051 MK-ValHOOPP@ihsmarkit.com Kamal.Sehgal@ihsmarkit.com Vrinda.Pal@ihsmarkit.com Managers: Sachin.Singhal@ihsmarkit.com Rajesh.Kumar2@ihsmarkit.com Toronto Staff: spencer.wiseman@ihsmarkit.com Abhinit.Kumar@ihsmarkit.com Red red@spglobal.com support@spglobal.com Markit Vol OTCDD@spglobal.com After Hours support: +1 877 762 7548 Corporate Action markitcorporateactions@ihsmarkit.com managedcorporateactions@ihsmarkit.com support@markit.com PE Vals (related to CIFC) MK-PEHOOPP@ihsmarkit.com DL-PE-PEValsSupport@ihsmarkit.com Ashwani.Rai@ihsmarkit.com Vendor Business Contact: Lucas Pettella's Team - 1st point of contact Portfolio Valuation: MK-ValHOOPP@ihsmarkit.com (sydney.workman@spglobal.com, nikita.zinchenko@spglobal.com) CDS Pricing Data: cdssupport@ihsmarkit.com EBS (Formerly known as DeltaOne): DeltaOneSupport@ihsmarkit.com OTC Derivatives Data: OTCDD@spglobal.com CDS Reference Data: red@spglobal.com Iboxx Indices: indices@ihsmarkit.com Cameron Lounsbery (Director - Account Management) Email: Cameron.Lounsbery@spglobal.com Phone: (416)304-6587 | AL29: V11_ITRAXX-ASIA_Red_Indices_YYYYMMDD.xml | AM29: GoldenSource Security Reference Pipeline | AN29: T+1 | AO29: T+1 | AP29: T+1 | AQ29: T+1 | AR29: T+1 | AS29: T+1 | AV29: 0.22569444
A30: 18 | G30: HOOPP_Markit_REDINDICES_CDX_FileLoad | H30: GC | J30: FileLoad | K30: Markit RED Credit Indices SOVX | L30: V10%20Red%20Indices%20Dynamic1724832091625.xml V11_ITRAXX-SOVX_Red_Indices_20250129.xml.dedup V11_ITRAXX-SOVX_Red_Indices_20250129.xml.inxdup V11_ITRAXX-SOVX_Red_Indices_20250129.xml | N30: 0.16666667 | O30: =N30 + TIME(2, 0, 0) -> 0.25 | P30: =N30+(Summary!$C$30)/24 -> 0.5625 | Q30: T+1 | R30: Every 5 mins | S30: 16 mins | T30: Daily(Mon-Fri) Daily(Tue-Sat) | AD30: 0.1875 | AE30: 0.21875 | AG30: HOOPP_Markit_REDINDICES_CDX_FileLoad | AH30: File Load Alert - GS MS Only (GS to chase Vendor directly) SLO Alert - GS MS, HOOPP | AI30: Vendor Technical Contact: General support@spglobal.com index_services@spglobal.com Michael.Stone@ihsmarkit.com For any escalation or urgent request: referencedataclientservice@spglobal.com SFTP issues: data.delivery@ihsmarkit.com CALL THIS NUMBER - GOES TO ALL INDIA SUPPORT STAFF: +91 120 611 8051 MK-ValHOOPP@ihsmarkit.com Kamal.Sehgal@ihsmarkit.com Vrinda.Pal@ihsmarkit.com Managers: Sachin.Singhal@ihsmarkit.com Rajesh.Kumar2@ihsmarkit.com Toronto Staff: spencer.wiseman@ihsmarkit.com Abhinit.Kumar@ihsmarkit.com Red red@spglobal.com support@spglobal.com Markit Vol OTCDD@spglobal.com After Hours support: +1 877 762 7548 Corporate Action markitcorporateactions@ihsmarkit.com managedcorporateactions@ihsmarkit.com support@markit.com PE Vals (related to CIFC) MK-PEHOOPP@ihsmarkit.com DL-PE-PEValsSupport@ihsmarkit.com Ashwani.Rai@ihsmarkit.com Vendor Business Contact: Lucas Pettella's Team - 1st point of contact Portfolio Valuation: MK-ValHOOPP@ihsmarkit.com (sydney.workman@spglobal.com, nikita.zinchenko@spglobal.com) CDS Pricing Data: cdssupport@ihsmarkit.com EBS (Formerly known as DeltaOne): DeltaOneSupport@ihsmarkit.com OTC Derivatives Data: OTCDD@spglobal.com CDS Reference Data: red@spglobal.com Iboxx Indices: indices@ihsmarkit.com Cameron Lounsbery (Director - Account Management) Email: Cameron.Lounsbery@spglobal.com Phone: (416)304-6587 | AL30: V11_ITRAXX-SOVX_Red_Indices_YYYYMMDD.xml | AM30: GoldenSource Security Reference Pipeline | AN30: T+1 | AO30: T+1 | AP30: T+1 | AQ30: T+1 | AR30: T+1 | AS30: T+1 | AV30: 0.22569444
A31: 19 | B31: Markit Load | C31: Standalone | E31: Standalone | F31: Price Master | H31: GC | J31: Markit Silver Prices - Price Denorm - Price Publishing | K31: Price Publishing | L31: Please remove this line - replaced by 11.1 | N31: 0.20833333 | P31: =N31+(Summary!$C$30)/24 -> 0.60416667 | Q31: T+1 | T31: Daily(Tue-Sat) | AD31: 0.1875 | AH31: Workflow fail Alert Load Alert - GS MS Only | AV31: 0
C32: Standalone | E32: Standalone | F32: Price Master | G32: HOOPP_PricePublishing_ReconMismatch | H32: GC | J32: WM and Makit CDX Silver Prices - Price Publishing | K32: Price Publishing | N32: 0.21875 | T32: Daily(Tue-Sat) | AM32: GoldenSource Market Data Solution Hub Pipeline | AN32: T+1 | AO32: T+1 | AP32: T+1 | AQ32: T+1 | AR32: T+1 | AS32: T+1
C33: Standalone | E33: Standalone | F33: Price Master | G33: HOOPP_PricePublishing_ReconMismatch_Monday | H33: GC | J33: Makit CDX Silver Prices - Price Publishing | K33: Price Publishing | N33: 0.21875 | T33: Mon | AM33: GoldenSource Market Data Solution Hub Pipeline | AN33: T+1 | AO33: T+1 | AP33: T+1 | AQ33: T+1 | AR33: T+1 | AS33: T+1
A34: 20 | G34: HOOPP_SnP_Full_FileLoad RATINGS_FULL | H34: GC | J34: FileLoad | K34: S&P Ratings (Issue & issuer) - Weekly Full | L34: spInstrumentToEntity20240915091505.entity spAssessmentData20240915091505.entity spRatingData20240915091505.entity spInstrumentToEntity20240915091505.security spAssessmentData20240915091505.security spRatingData20240915091505.security spSecurityLevelData20240915091505.security spInstrumentToEntity20240915091505.final spRatingData20240915091505.final spSecurityLevelData20240915091505.final spAssessmentData20240915091505.final | N34: 0.25 | O34: =N34 + TIME(2, 0, 0) -> 0.33333333 | P34: =N34+(Summary!$C$30)/24 -> 0.64583333 | Q34: T+1 | R34: Every 10 mins | S34: 21 mins | T34: Sun | AD34: 0.27083333 | AE34: 0.29166667 | AH34: File Load Alert - GS MS Only (GS to chase Vendor directly) SLO Alert - GS MS, HOOPP | AI34: Product.Notification <Product.Notification@spglobal.com> | AL34: spInstrumentToEntityYYYYMMDD??????.entity | AM34: GoldenSource Security Reference Pipeline | AN34: T | AU34: T | AV34: 0.29861111
A35: 39 | C35: Standalone | E35: Standalone | G35: HOOPP_WM_FileLoad | H35: GC | J35: FileLoad | K35: WMR | L35: wmr1911.csv rusd19112024.csv | N35: 0.47916667 | O35: =N35 + TIME(2, 0, 0) -> 0.5625 | T35: Daily(Mon-Fri) | U35: WM_HOLIDAY | AD35: 0.5 | AE35: 0.51041667 | AG35: HOOPP_WM_FileLoad | AI35: wmr.ops <wmr.ops@lseg.com> wmr.ops@mrelay.lseg.com | AV35: 0.51041667
A36: 39.1 | B36: 39 | C36: Standalone | E36: Standalone | F36: Price Master | H36: GC | J36: WM Silver Prices - Price Denorm - Price Publishing | K36: Price Publishing | L36: rusdDDMMYYYY_preprocessed.csv wmrDDMM_preprocessed.csv | N36: 0.47916667 | T36: Daily(Mon-Fri) | U36: WM_HOLIDAY | AD36: 0.5 | AE36: 0.51041667 | AG36: HOOPP_WM_FileLoad | AI36: wmr.ops <wmr.ops@lseg.com> wmr.ops@mrelay.lseg.com | AL36: wmrDDMM_preprocessed.csv | AM36: GoldenSource Market Data Solution Hub Pipeline | AN36: T | AO36: T | AP36: T | AQ36: T | AR36: T | AS36: T | AV36: 0.51736111
A37: 21 | C37: Standalone | E37: Standalone | G37: HOOPP_SCD_3PM_FileLoad | H37: GC | J37: FileLoad | K37: Simcorp | L37: SCD_SMF_280824150141.csv | N37: 0.625 | O37: =N37 + TIME(2, 0, 0) -> 0.70833333 | P37: =N37+(Summary!$C$30)/24 -> 1.0208333 | Q37: T | R37: Every 3 mins | S37: 10 mins | T37: Daily(Mon-Fri) | Z37: This SMF load is used for SVC price workflow. 3:10PM SMF load does not exist in PACE current state | AB37: Y | AD37: 0.64583333 | AE37: 0.66666667 | AG37: HOOPP_SCD_3PM_FileLoad | AH37: File Load Alert - GS MS Only (GS to chase Vendor directly) SLO Alert - GS MS, HOOPP | AI37: DXC Overnight Tier 1 <dxcovernighttier1@hoopp.com>; Golden Source Operations <goldensourceoperations@hoopp.com>; ISG-DTS-Operations <isg-dts-operations@hoopp.com> | AJ37: e.g. alert after 1 hour, send email, fail job, run job anyway, etc. | AV37: 0.66666667
A38: 22 | F38: Price Master | G38: HOOPP_BB_FX_REQ_Schedule | H38: GC | J38: BB Request | K38: BB Followon Request FXSOI | L38: GS.BB.FX.out.20240828 | N38: 0.66666667 | P38: =N38+(Summary!$C$30)/24 -> 1.0625 | Q38: T | R38: Every 1 min | S38: 2 mins | T38: Daily(Mon-Fri) | Z38: FX rate request to Bloomberg | AA38: REQUEST.BBPS_FX | AB38: Y | AD38: 0.71875 | AH38: File Load Alert - GS MS Only (GS to chase Vendor directly) SLO Alert - GS MS, HOOPP | AI38: http://service.bloomberg.com Urgent issues: 1-212-617-4390 Global Technical Support: 1-212-318-2000; DXC Contact: DXC Overnight Tier 1 <dxcovernighttier1@hoopp.com> | AV38: 0
A39: 23 | B39: 22 | C39: Chain | E39: HOOPP_BB_FX_Resp_Schedule | F39: Price Master | G39: HOOPP_BB_Trig_FX_FileLoad | H39: GC | J39: FileLoad | K39: BB Followon Response FXSOI | L39: GS.BB.FX.out.20240828 | N39: 0.70833333 | P39: =N39+(Summary!$C$30)/24 -> 1.1041667 | Q39: T | T39: Daily(Mon-Fri) | V39: HOOPP_EVT_BBScheduledResponseWrapper | W39: HOOPP_BB_Trig_FX_FileLoad.json | Z39: FX rate return from Bloomberg | AA39: RETURN.BBPS_FX | AB39: Y | AD39: 0.71875 | AE39: 0.72916667 | AG39: HOOPP_BB_FX_Resp_Schedule | AH39: File Load Alert - GS MS Only (GS to chase Vendor directly) SLO Alert - GS MS, HOOPP | AI39: http://service.bloomberg.com Urgent issues: 1-212-617-4390 Global Technical Support: 1-212-318-2000; DXC Contact: DXC Overnight Tier 1 <dxcovernighttier1@hoopp.com> | AV39: 0.72916667
A40: 24 | B40: 23 | C40: Chain | E40: HOOPP_BB_FX_Resp_Schedule | F40: Price Master | H40: GC | J40: Pricing (Validation) | K40: Final FX Price Validation + Publishing | L40: GS.BB.FX.out.20250128 | N40: 0.70833333 | P40: =N40+(Summary!$C$30)/24 -> 1.1041667 | Q40: T | T40: Daily(Mon-Fri) | AB40: Y | AD40: 0.71875 | AE40: 0.72916667 | AG40: HOOPP_BB_FX_Resp_Schedule | AH40: File Load Alert - GS MS Only (GS to chase Vendor directly) SLO Alert - GS MS, HOOPP | AI40: http://service.bloomberg.com Urgent issues: 1-212-617-4390 Global Technical Support: 1-212-318-2000; DXC Contact: DXC Overnight Tier 1 <dxcovernighttier1@hoopp.com> | AJ40: URGENT TIME CRITICAL PUBLISH TO SF Assumption is that GS will only publish the validated prices | AL40: GS.BB.FX.out.YYYYMMDD | AM40: GoldenSource Market Data Solution Hub Pipeline | AN40: T | AO40: T | AP40: T | AQ40: T | AR40: T | AS40: T | AV40: 0.73611111
...

Sheet Pricing ADITLO Simplified
A1: TimeLine | B1: Data for? | C1: Time Trigerred (EST/EDT) | D1: Time Trigerred (IST) | E1: Key Figures Loaded? | F1: Vendor | G1: File Load? | H1: Price Load | I1: Price Validation? | J1: Price Denormalization? | K1: Publishing? | L1: Request SOI | M1: Denorm SOI | N1: Validation SOI | O1: Creation of SOI | P1: HOOPP Comment
A2: T | B2: T | C2: 0.70833333 | D2: =C2+Summary!$C$30/24 -> 1.1041667 | E2: No | F2: FX | G2: Yes | H2: Yes | I2: Yes | J2: Yes | K2: Yes | L2: FX_SOI | M2: FX_SOI | N2: FX_SOI | O2: FX_SOI: Manual One Time
A3: T | B3: T | C3: 0.75 | D3: =C3+Summary!$C$30/24 -> 1.1458333 | E3: Yes | F3: FTSE | G3: Yes | H3: Yes | I3: No | J3: No | K3: No | O3: FTSE_SOI
A4: T | B4: T-1 | C4: 0.75 | D4: =C4+Summary!$C$30/24 -> 1.1458333 | E4: No | F4: SCD | G4: Yes | H4: No | O4: OTCSOI
A5: T | B5: T | C5: 0.8125 | D5: =C5+Summary!$C$30/24 -> 1.2083333 | E5: No | F5: SVC | G5: Yes | H5: Yes | I5: No | J5: No | K5: No | L5: All Bonds from HOOPP SOI
A6: T | B6: T | C6: 0.82291667 | D6: =C6+Summary!$C$30/24 -> 1.21875 | F6: SVC/FTSE | G6: No | I6: Yes | J6: Yes | K6: Yes | M6: FTSE_SOI, EOD_BONDS | N6: EOD_BONDS
A7: T | B7: T | C7: 0.95833333 | D7: =C7+Summary!$C$30/24 -> 1.3541667 | E7: No | F7: SCD | G7: Yes | H7: No | I7: No | J7: No | K7: No | O7: HOOPP SOI(Superset), EOD_BONDS(Some Bonds from HOOP SOI), EOD_EQ(Some Equities from Hoop SOI)
A8: T+1 | B8: T-1 | C8: 0.027777778 | D8: =C8+Summary!$C$30/24 -> 0.42361111 | E8: Yes | F8: BB | G8: Yes | H8: yes | I8: Yes | J8: Yes | K8: Yes | L8: HOOP_SOI | M8: HOOPP SOI,REFRATE_SOI,FTSE_SOI,GENERIC_TICKERS_SOI | N8: EOD_EQ
A9: T | B9: T | C9: 0.84722222 | E9: Yes | F9: Markit OTC (Cred) | G9: Yes | H9: Yes | I9: No | J9: Yes | K9: Yes | M9: MarkitSOI_CDX_TRANCHE | N9: MarkitSOI_CDX_TRANCHE | P9: Depends on 38
A10: T | B10: T | C10: 0.85416667 | E10: Yes | F10: ICE | G10: Yes | H10: Yes | I10: Yes | J10: Yes | K10: Yes | M10: MarkitSOI_CC_CDS | N10: MarkitSOI_CC_CDS | P10: Depends on 36
A11: T | B11: T | C11: 0.9375 | E11: Yes | F11: ICE | G11: Yes | H11: Yes | I11: No | J11: Yes | K11: Yes | M11: ICE_SOI | P11: Depends on 36 Key Figures & Pricing published for all ICE securities?
A12: T | B12: T | C12: 0.9375 | E12: Yes | F12: Markit OTC | G12: Yes | H12: Yes | I12: No | J12: Yes | K12: Yes | M12: MarkitSOI_CDX_CDS | N12: MarkitSOI_CDX_CDS | P12: Not needed - no files impacting CDX_CDS loaded at this time
A13: T+1 | B13: T-1 | C13: 0.0625 | E13: Yes | F13: Markit OTC (SG_DAILY) | G13: Yes | H13: Yes | I13: Yes | J13: Yes | K13: Yes | M13: MarkitSOI_CDX_TRANCHE | N13: MarkitSOI_CDX_TRANCHE | P13: Depends on 35.1 | Q13: Updated Time Triggered Until and Business SLO on main tab
A14: T+1 | B14: T-1 | C14: 0.0625 | E14: Yes | F14: Markit OTC (SG_DAILY_2) | G14: Yes | H14: Yes | I14: Yes | J14: Yes | K14: Yes | M14: MarkitSOI_ABX | N14: MarkitSOI_ABX | P14: Depends on 35.2
A15: T+1 | B15: T-1 | C15: 0.0625 | E15: Yes | F15: Markit OTC (SG_DAILY) | G15: Yes | H15: Yes | I15: Yes | J15: Yes | K15: Yes | M15: MarkitSOI_BESPOKE | N15: MarkitSOI_BESPOKE | P15: Depends on 35.1
A16: T+1 | B16: T-1 | C16: 0.0625 | E16: Yes | F16: Markit OTC (SG_DAILY_2) | G16: Yes | H16: Yes | I16: Yes | J16: Yes | K16: Yes | M16: MarkitSOI_CDX_OPT | N16: MarkitSOI_CDX_OPT | P16: Depends on 35.2
A17: T+1 | B17: T-1 | C17: 0.0625 | E17: Yes | F17: Markit OTC (SG_DAILY_2) | G17: Yes | H17: Yes | I17: No | J17: Yes | K17: Yes | M17: MarkitSOI_CC_CDX_CDS | P17: Depends on 35.2
A18: T+1 | B18: T-1 | C18: 0.0625 | E18: Yes | F18: Markit OTC (SG_DAILY_2) | G18: Yes | H18: Yes | I18: No | J18: Yes | K18: Yes | M18: MarkitSOI_CDX_CDS | P18: Depends on 35.2
A19: T+1 | B19: T-1 | C19: 0.10416667 | D19: =C19+Summary!$C$30/24 -> 0.5 | E19: Yes | F19: Markit (Credit Index Pricing) | G19: Yes | H19: Yes | I19: No | J19: Yes | K19: Yes | P19: Depends on 10; mentioned as part of row 10.1 in the main ADITLO tab Key Figures & Pricing published for all Markit Credit Index securities.
A20: T+1 | B20: T-1 | C20: 0.10416667 | E20: Yes | F20: Markit CI/CDS | G20: Yes | H20: Yes | I20: Yes | J20: Yes | K20: Yes | M20: MarkitSOI_CC_CDX_CDS | N20: MarkitSOI_CC_CDX_CDS | P20: Depends on 36 & 10; however, if 10 is very late, can CC_CDX_CDS price validation run anyway at 3:30 am?
A21: T+1 | B21: T-1 | C21: 0.10416667 | E21: Yes | F21: Markit CI/CDS | G21: Yes | H21: Yes | I21: Yes | J21: Yes | K21: Yes | M21: MarkitSOI_CDX_CDS | N21: MarkitSOI_CDX_CDS | P21: Depends on 10
A22: T+1 | B22: T-1 | C22: 0.10416667 | D22: =C22+Summary!$C$30/24 -> 0.5 | E22: Yes | F22: Markit (Composite CDS) | G22: Yes | H22: Yes | I22: No | J22: Yes | K22: Yes | P22: Added as row 11.1 on ADITLO Key Figures & Pricing published for all Markit Spread securities.
A23: T | B23: T | C23: 0.47916667 | F23: World Markets | G23: Yes | H23: Yes | I23: No | J23: Yes | K23: Yes | M23: FX_WM_SOI
A24: T | B24: T | C24: 0.9375 | F24: Northern Trust | G24: Yes | H24: Yes | I24: No | J24: Yes | K24: Yes | M24: NTFX_SOI
A25: T | B25: T | C25: 0.89583333 | F25: LCH | G25: Yes | H25: Yes | I25: Yes | J25: Yes | K25: Yes | M25: LCH_SOI | N25: LCH_SOI

Sheet Legends
C2: ADITLO | D2: A Day In The Life Of "Customer" | G2: Note: 1) NO business Jobs will run on Weekends. 2) Some ADHOC jobs are necessary for NPORT data reporting and need to be manually trigerred when the file arrives on the FTP. JNAM will inform via email about file upload. 3) JNAM always provides files to load on the FTP. They notify on emails.
C3: SM | D3: Security Master
C4: DWH | D4: Data Warehouse
C5: CST/CDT | D5: Central Standard Time/Central Daylight Time
C6: EST/EDT | D6: Eastern Standard Time/Eastern Daylight Time
C7: IST | D7: Indian Standard Time
C8: AS | D8: Application Server
C9: SLA | D9: Service Level Agreement
C10: SLO | D10: Service Level Objectives
C11: SLI | D11: Service Level Indicators
C13: Header of ADITLO worksheet - description
C15: Job # | D15: task number in the order of execution on a business day
C16: Depends Job # | D16: dependednt task number in the order of execution if Chains used
C17: Job Chain Name | D17: name of the job chain in the job scheduler
C18: Task Name in Job Scheduler | D18: name used to identify the task in the Job Scheduler list of jobs for JNAM
C19: Schema | D19: schema used to process or publish the inbound/outbound files respectively.
C20: Task Type | D20: type of task - file load, publishing, alerts or miscellaneous
C21: Job Category | D21: type of job - standalone or job chain in the job scheduler
C22: Input or Output File Names | D22: name of the inbound or outbound file(s)
C23: Time Trigerred (CST/CDT) | D23: time of execution in CST or CDT
C24: Time Trigerred (EST/EDT) | D24: time of execution in EST or EDT
C25: Time Trigerred (IST) | D25: time of execution in IST
C26: Frequency | D26: frequency of job executions - daily, monthly etc
... C37: Alert Send To | D37: audience for the alert

Sheet Calendar Data
A1: CAD1STOCKMARKET | G1: US1STOCKMARKET | N1: MARKIT_HOLIDAY | Q1: MARKIT_HOLIDAYPLUS1 | T1: SVC_HOLIDAY | U1: (US & CAD Holidays) | W1: WM_HOLIDAY
A2: EventYear | B2: EventDate | C2: EventDayOfWeek | D2: EventName | G2: EventYear | H2: EventDate | I2: EventDayOfWeek | J2: EventName | N2: EventYear | O2: EventDate | Q2: EventYear | R2: EventDate | T2: EventYear | U2: EventDate | W2: EventYear | X2: EventDate
A3: 2024 | B3: 20240101 | C3: Mon | D3: New Year's Day | G3: 2024 | H3: 20240101 | I3: Mon | J3: New Year's Day | N3: 2024 | O3: 20240101 | Q3: 2024 | R3: 20240102 | T3: 2025 | U3: 20250101 | W3: 2025 | X3: 20250101
A4: 2024 | B4: 20240219 | C4: Mon | D4: Family Day | G4: 2024 | H4: 20240115 | I4: Mon | J4: Martin Luther King Jr. Day | N4: 2024 | O4: 20241225 | Q4: 2024 | R4: 20241226 | T4: 2025 | U4: 20250217 | W4: 2025 | X4: 20250418
A5: 2024 | B5: 20240329 | C5: Fri | D5: Good Friday | G5: 2024 | H5: 20240219 | I5: Mon | J5: Presidents' Day | N5: 2025 | O5: 20250101 | Q5: 2025 | R5: 20250102 | T5: 2025 | U5: 20250418 | W5: 2025 | X5: 20251225
A6: 2024 | B6: 20240520 | C6: Mon | D6: Victoria/Patriots' Day | G6: 2024 | H6: 20240329 | I6: Fri | J6: Good Friday | N6: 2025 | O6: 20251225 | Q6: 2025 | R6: 20251226 | T6: 2025 | U6: 20250901 | W6: 2026 | X6: 20260101
A7: 2024 | B7: 20240701 | C7: Mon | D7: Canada Day | G7: 2024 | H7: 20240527 | I7: Mon | J7: Memorial Day | T7: 2025 | U7: 20251225 | W7: 2026 | X7: 20260403
A8: 2024 | B8: 20240805 | C8: Mon | D8: Civic Holiday | G8: 2024 | H8: 20240619 | I8: Wed | J8: Juneteenth National Independence Day | N8: ICE_LCH_HOLIDAY | T8: 2026 | U8: 20260101 | W8: 2026 | X8: 20261225
A9: 2024 | B9: 20240902 | C9: Mon | D9: Labour Day | G9: 2024 | H9: 20240704 | I9: Thu | J9: Independence Day | N9: 2025 | O9: 20250101 | T9: 2026 | U9: 20260216
A10: 2024 | B10: 20241014 | C10: Mon | D10: Thanksgiving | G10: 2024 | H10: 20240902 | I10: Mon | J10: Labor Day | T10: 2026 | U10: 20260403
A11: 2024 | B11: 20241225 | C11: Wed | D11: Christmas | G11: 2024 | H11: 20241014 | I11: Mon | J11: Columbus Day | N11: SNP_QUARTERLY_CAL | T11: 2026 | U11: 20260907
A12: 2024 | B12: 20241226 | C12: Thu | D12: Boxing Day | G12: 2024 | H12: 20241111 | I12: Mon | J12: Veterans' Day | N12: 2025 | O12: 20250105 | T12: 2026 | U12: 20261225
A13: 2025 | B13: 20250101 | C13: Wed | D13: New Year's Day | G13: 2024 | H13: 20241128 | I13: Thu | J13: Thanksgiving | N13: 2025 | O13: 20250406
A14: 2025 | B14: 20250217 | C14: Mon | D14: Family Day | G14: 2024 | H14: 20241225 | I14: Wed | J14: Christmas | N14: 2025 | O14: 20250706
A15: 2025 | B15: 20250418 | C15: Fri | D15: Good Friday | G15: 2025 | H15: 20250101 | I15: Wed | J15: New Year's Day | N15: 2025 | O15: 20251006
A16: 2025 | B16: 20250519 | C16: Mon | D16: Victoria/Patriots' Day | G16: 2025 | H16: 20250120 | I16: Mon | J16: Martin Luther King Jr. Day
A17: 2025 | B17: 20250701 | C17: Tue | D17: Canada Day | G17: 2025 | H17: 20250217 | I17: Mon | J17: Presidents' Day
A18: 2025 | B18: 20250804 | C18: Mon | D18: Civic Holiday | G18: 2025 | H18: 20250418 | I18: Fri | J18: Good Friday
A19: 2025 | B19: 20250901 | C19: Mon | D19: Labour Day | G19: 2025 | H19: 20250526 | I19: Mon | J19: Memorial Day
A20: 2025 | B20: 20251013 | C20: Mon | D20: Thanksgiving | G20: 2025 | H20: 20250619 | I20: Thu | J20: Juneteenth National Independence Day
A21: 2025 | B21: 20251225 | C21: Thu | D21: Christmas | G21: 2025 | H21: 20250704 | I21: Fri | J21: Independence Day
A22: 2025 | B22: 20251226 | C22: Fri | D22: Boxing Day | G22: 2025 | H22: 20250901 | I22: Mon | J22: Labor Day
G23: 2025 | H23: 20251127 | I23: Thu | J23: Thanksgiving
A24: CAD2BANKHOLIDAY | G24: 2025 | H24: 20251225 | I24: Thu | J24: Christmas
A25: EventYear | B25: EventDate | C25: EventDayOfWeek | D25: EventName
A26: 2024 | B26: 20240101 | C26: Mon | D26: New Year's Day
A27: 2024 | B27: 20240219 | C27: Mon | D27: Family Day
A28: 2024 | B28: 20240329 | C28: Fri | D28: Good Friday
A29: 2024 | B29: 20240520 | C29: Mon | D29: Victoria/Patriots' Day
A30: 2024 | B30: 20240701 | C30: Mon | D30: Canada Day
A31: 2024 | B31: 20240805 | C31: Mon | D31: Civic Holiday
A32: 2024 | B32: 20240902 | C32: Mon | D32: Labour Day
A33: 2024 | B33: 20240930 | C33: Mon | D33: National Truth and Reconciliation Day
A34: 2024 | B34: 20241014 | C34: Mon | D34: Thanksgiving
A35: 2024 | B35: 20241111 | C35: Mon | D35: Remembrance Day
A36: 2024 | B36: 20241225 | C36: Wed | D36: Christmas
A37: 2024 | B37: 20241226 | C37: Thu | D37: Boxing Day
... A49: 2025 | B49: 20251226 | C49: Fri | D49: Boxing Day

Sheet Custom Pipelines
A1: Pipeline Name | B1: S3 Folder | C1: File Type | D1: Table Name | E1: Event Enabled
A2: FTSE IDXSummary DBI | B2: s3://gs-hp-us-east-1-uat-snowflake/raw_vendor_files/ftse/idxsummary_dbi/ | C2: CSV | D2: STRUCTURED.FTSE_IDXSUMMARY_DBI | E2: TRUE
A3: FTSE IDXSummary RRBI | B3: s3://gs-hp-us-east-1-uat-snowflake/raw_vendor_files/ftse/idxsummary_rrbi/ | C3: CSV | D3: STRUCTURED.FTSE_IDXSUMMARY_RRBI | E3: TRUE
A4: FTSE IDXDetails DBI UO | B4: s3://gs-hp-us-east-1-uat-snowflake/raw_vendor_files/ftse/idxdetail_dbi_uo/ | C4: CSV | D4: STRUCTURED.FTSE_IDXDETAILS_DBI_UO | E4: TRUE
A5: FTSE IDXDetails RRBI TR | B5: s3://gs-hp-us-east-1-uat-snowflake/raw_vendor_files/ftse/idxdetail_rrbi_tr/ | C5: CSV | D5: STRUCTURED.FTSE_IDXDETAILS_RRBI_TR | E5: TRUE
A6: FTSE IDXDetails RRBI UO | B6: s3://gs-hp-us-east-1-uat-snowflake/raw_vendor_files/ftse/idxdetail_rrbi_uo/ | C6: CSV | D6: STRUCTURED.FTSE_IDXDETAILS_RRBI_UO | E6: TRUE
A7: FTSE IDXDetails DBI TR | B7: s3://gs-hp-us-east-1-uat-snowflake/raw_vendor_files/ftse/idxdetail_dbi_tr/ | C7: CSV | D7: STRUCTURED.FTSE_IDXDETAILS_DBI_TR | E7: TRUE
A8: FTSE SCMMKT | B8: s3://gs-hp-us-east-1-uat-snowflake/raw_vendor_files/ftse/scmmkt/ | C8: CSV | D8: STRUCTURED.FTSE_SCMMKT | E8: TRUE
A9: Bloomberg | B9: s3://gs-hp-us-east-1-uat-snowflake/raw_vendor_files/bb_per_sec/ | C9: BLOOMBERG | D9: STRUCTURED.BLOOMBERG | E9: TRUE
A10: SCD | B10: s3://gs-hp-us-east-1-uat-snowflake/raw_vendor_files/scd/ | C10: CSV | D10: STRUCTURED.SCD | E10: TRUE
A11: SnP Ratings | B11: s3://gs-hp-us-east-1-uat-snowflake/raw_vendor_files/snp_ratings/ | C11: S&P | D11: STRUCTURED.SNP_RATINGS | E11: TRUE
A12: Moodys Instrument Ratings | B12: s3://gs-hp-us-east-1-uat-snowflake/raw_vendor_files/moodys/instruments_ratings/ | C12: MOODYS: Ratings | D12: STRUCTURED.MOODYS_INSTRUMENT_RATINGS | E12: TRUE
